[2022-07-05 18:03:50,476] {taskinstance.py:1032} INFO - Dependencies all met for <TaskInstance: LocalIngestionDag.ingest scheduled__2022-01-02T06:00:00+00:00 [queued]>
[2022-07-05 18:03:50,519] {taskinstance.py:1032} INFO - Dependencies all met for <TaskInstance: LocalIngestionDag.ingest scheduled__2022-01-02T06:00:00+00:00 [queued]>
[2022-07-05 18:03:50,521] {taskinstance.py:1238} INFO - 
--------------------------------------------------------------------------------
[2022-07-05 18:03:50,523] {taskinstance.py:1239} INFO - Starting attempt 7 of 7
[2022-07-05 18:03:50,525] {taskinstance.py:1240} INFO - 
--------------------------------------------------------------------------------
[2022-07-05 18:03:50,562] {taskinstance.py:1259} INFO - Executing <Task(PythonOperator): ingest> on 2022-01-02 06:00:00+00:00
[2022-07-05 18:03:50,577] {standard_task_runner.py:52} INFO - Started process 3908 to run task
[2022-07-05 18:03:50,599] {standard_task_runner.py:76} INFO - Running: ['***', 'tasks', 'run', 'LocalIngestionDag', 'ingest', 'scheduled__2022-01-02T06:00:00+00:00', '--job-id', '79', '--raw', '--subdir', 'DAGS_FOLDER/data_ingestion_local.py', '--cfg-path', '/tmp/tmpq0efapze', '--error-file', '/tmp/tmpmyw7xw8z']
[2022-07-05 18:03:50,603] {standard_task_runner.py:77} INFO - Job 79: Subtask ingest
[2022-07-05 18:03:50,835] {logging_mixin.py:109} INFO - Running <TaskInstance: LocalIngestionDag.ingest scheduled__2022-01-02T06:00:00+00:00 [running]> on host ec047ba4deb7
[2022-07-05 18:03:51,067] {warnings.py:99} WARNING - /home/***/.local/lib/python3.6/site-packages/***/utils/context.py:152: AirflowContextDeprecationWarning: Accessing 'execution_date' from the template is deprecated and will be removed in a future version. Please use 'data_interval_start' or 'logical_date' instead.
  warnings.warn(_create_deprecation_warning(key, self._deprecation_replacements[key]))

[2022-07-05 18:03:51,143] {taskinstance.py:1426} INFO - Exporting the following env vars:
AIRFLOW_CTX_DAG_OWNER=***
AIRFLOW_CTX_DAG_ID=LocalIngestionDag
AIRFLOW_CTX_TASK_ID=ingest
AIRFLOW_CTX_EXECUTION_DATE=2022-01-02T06:00:00+00:00
AIRFLOW_CTX_DAG_RUN_ID=scheduled__2022-01-02T06:00:00+00:00
[2022-07-05 18:03:51,147] {logging_mixin.py:109} INFO - yellow_taxi_2022_01 /opt/***/output_2022-01.csv
[2022-07-05 18:03:51,151] {logging_mixin.py:109} INFO - created engine
[2022-07-05 18:03:51,278] {logging_mixin.py:109} INFO - connection established successfully, inserting data...
[2022-07-05 18:03:51,585] {logging_mixin.py:109} INFO -               <?xml version="1.0" encoding="UTF-8"?>
0  <Error><Code>NoSuchKey</Code><Message>The spec...
[2022-07-05 18:03:51,587] {taskinstance.py:1700} ERROR - Task failed with exception
Traceback (most recent call last):
  File "/home/airflow/.local/lib/python3.6/site-packages/airflow/models/taskinstance.py", line 1329, in _run_raw_task
    self._execute_task_with_callbacks(context)
  File "/home/airflow/.local/lib/python3.6/site-packages/airflow/models/taskinstance.py", line 1455, in _execute_task_with_callbacks
    result = self._execute_task(context, self.task)
  File "/home/airflow/.local/lib/python3.6/site-packages/airflow/models/taskinstance.py", line 1511, in _execute_task
    result = execute_callable(context=context)
  File "/home/airflow/.local/lib/python3.6/site-packages/airflow/operators/python.py", line 174, in execute
    return_value = self.execute_callable()
  File "/home/airflow/.local/lib/python3.6/site-packages/airflow/operators/python.py", line 185, in execute_callable
    return self.python_callable(*self.op_args, **self.op_kwargs)
  File "/opt/airflow/dags/ingest_script.py", line 37, in ingest_callable
    df.tpep_pickup_datetime = pd.to_datetime(df.tpep_pickup_datetime)
  File "/home/airflow/.local/lib/python3.6/site-packages/pandas/core/generic.py", line 5141, in __getattr__
    return object.__getattribute__(self, name)
AttributeError: 'DataFrame' object has no attribute 'tpep_pickup_datetime'
[2022-07-05 18:03:51,648] {taskinstance.py:1277} INFO - Marking task as FAILED. dag_id=LocalIngestionDag, task_id=ingest, execution_date=20220102T060000, start_date=20220705T180350, end_date=20220705T180351
[2022-07-05 18:03:51,691] {standard_task_runner.py:92} ERROR - Failed to execute job 79 for task ingest
Traceback (most recent call last):
  File "/home/airflow/.local/lib/python3.6/site-packages/airflow/task/task_runner/standard_task_runner.py", line 85, in _start_by_fork
    args.func(args, dag=self.dag)
  File "/home/airflow/.local/lib/python3.6/site-packages/airflow/cli/cli_parser.py", line 48, in command
    return func(*args, **kwargs)
  File "/home/airflow/.local/lib/python3.6/site-packages/airflow/utils/cli.py", line 92, in wrapper
    return f(*args, **kwargs)
  File "/home/airflow/.local/lib/python3.6/site-packages/airflow/cli/commands/task_command.py", line 298, in task_run
    _run_task_by_selected_method(args, dag, ti)
  File "/home/airflow/.local/lib/python3.6/site-packages/airflow/cli/commands/task_command.py", line 107, in _run_task_by_selected_method
    _run_raw_task(args, ti)
  File "/home/airflow/.local/lib/python3.6/site-packages/airflow/cli/commands/task_command.py", line 184, in _run_raw_task
    error_file=args.error_file,
  File "/home/airflow/.local/lib/python3.6/site-packages/airflow/utils/session.py", line 70, in wrapper
    return func(*args, session=session, **kwargs)
  File "/home/airflow/.local/lib/python3.6/site-packages/airflow/models/taskinstance.py", line 1329, in _run_raw_task
    self._execute_task_with_callbacks(context)
  File "/home/airflow/.local/lib/python3.6/site-packages/airflow/models/taskinstance.py", line 1455, in _execute_task_with_callbacks
    result = self._execute_task(context, self.task)
  File "/home/airflow/.local/lib/python3.6/site-packages/airflow/models/taskinstance.py", line 1511, in _execute_task
    result = execute_callable(context=context)
  File "/home/airflow/.local/lib/python3.6/site-packages/airflow/operators/python.py", line 174, in execute
    return_value = self.execute_callable()
  File "/home/airflow/.local/lib/python3.6/site-packages/airflow/operators/python.py", line 185, in execute_callable
    return self.python_callable(*self.op_args, **self.op_kwargs)
  File "/opt/airflow/dags/ingest_script.py", line 37, in ingest_callable
    df.tpep_pickup_datetime = pd.to_datetime(df.tpep_pickup_datetime)
  File "/home/airflow/.local/lib/python3.6/site-packages/pandas/core/generic.py", line 5141, in __getattr__
    return object.__getattribute__(self, name)
AttributeError: 'DataFrame' object has no attribute 'tpep_pickup_datetime'
[2022-07-05 18:03:51,764] {local_task_job.py:154} INFO - Task exited with return code 1
[2022-07-05 18:03:52,047] {local_task_job.py:264} INFO - 0 downstream tasks scheduled from follow-on schedule check
