[2022-08-05 17:11:38,499] {taskinstance.py:1032} INFO - Dependencies all met for <TaskInstance: move_gcs_trip_data_to_bq_workflow2.bigquery_external_table_task_fhv scheduled__2022-08-04T00:00:00+00:00 [queued]>
[2022-08-05 17:11:38,556] {taskinstance.py:1032} INFO - Dependencies all met for <TaskInstance: move_gcs_trip_data_to_bq_workflow2.bigquery_external_table_task_fhv scheduled__2022-08-04T00:00:00+00:00 [queued]>
[2022-08-05 17:11:38,564] {taskinstance.py:1238} INFO - 
--------------------------------------------------------------------------------
[2022-08-05 17:11:38,566] {taskinstance.py:1239} INFO - Starting attempt 1 of 2
[2022-08-05 17:11:38,567] {taskinstance.py:1240} INFO - 
--------------------------------------------------------------------------------
[2022-08-05 17:11:38,618] {taskinstance.py:1259} INFO - Executing <Task(BigQueryCreateExternalTableOperator): bigquery_external_table_task_fhv> on 2022-08-04 00:00:00+00:00
[2022-08-05 17:11:38,626] {standard_task_runner.py:52} INFO - Started process 6813 to run task
[2022-08-05 17:11:38,674] {standard_task_runner.py:76} INFO - Running: ['***', 'tasks', 'run', 'move_gcs_trip_data_to_bq_workflow2', 'bigquery_external_table_task_fhv', 'scheduled__2022-08-04T00:00:00+00:00', '--job-id', '104', '--raw', '--subdir', 'DAGS_FOLDER/gcs_to_bq.py', '--cfg-path', '/tmp/tmpvwyy0uvs', '--error-file', '/tmp/tmpe05svn_z']
[2022-08-05 17:11:38,692] {standard_task_runner.py:77} INFO - Job 104: Subtask bigquery_external_table_task_fhv
[2022-08-05 17:11:39,473] {logging_mixin.py:109} INFO - Running <TaskInstance: move_gcs_trip_data_to_bq_workflow2.bigquery_external_table_task_fhv scheduled__2022-08-04T00:00:00+00:00 [running]> on host a02ae1da6c7b
[2022-08-05 17:11:39,736] {taskinstance.py:1426} INFO - Exporting the following env vars:
AIRFLOW_CTX_DAG_OWNER=***
AIRFLOW_CTX_DAG_ID=move_gcs_trip_data_to_bq_workflow2
AIRFLOW_CTX_TASK_ID=bigquery_external_table_task_fhv
AIRFLOW_CTX_EXECUTION_DATE=2022-08-04T00:00:00+00:00
AIRFLOW_CTX_DAG_RUN_ID=scheduled__2022-08-04T00:00:00+00:00
[2022-08-05 17:11:39,740] {crypto.py:82} WARNING - empty cryptography key - values will not be stored encrypted.
[2022-08-05 17:11:40,484] {taskinstance.py:1700} ERROR - Task failed with exception
Traceback (most recent call last):
  File "/home/airflow/.local/lib/python3.7/site-packages/airflow/models/taskinstance.py", line 1329, in _run_raw_task
    self._execute_task_with_callbacks(context)
  File "/home/airflow/.local/lib/python3.7/site-packages/airflow/models/taskinstance.py", line 1455, in _execute_task_with_callbacks
    result = self._execute_task(context, self.task)
  File "/home/airflow/.local/lib/python3.7/site-packages/airflow/models/taskinstance.py", line 1511, in _execute_task
    result = execute_callable(context=context)
  File "/home/airflow/.local/lib/python3.7/site-packages/airflow/providers/google/cloud/operators/bigquery.py", line 1196, in execute
    table_resource=self.table_resource,
  File "/home/airflow/.local/lib/python3.7/site-packages/airflow/providers/google/common/hooks/base_google.py", line 430, in inner_wrapper
    return func(self, *args, **kwargs)
  File "/home/airflow/.local/lib/python3.7/site-packages/airflow/providers/google/cloud/hooks/bigquery.py", line 408, in create_empty_table
    table=table, exists_ok=exists_ok, retry=retry
  File "/home/airflow/.local/lib/python3.7/site-packages/google/cloud/bigquery/client.py", line 755, in create_table
    timeout=timeout,
  File "/home/airflow/.local/lib/python3.7/site-packages/google/cloud/bigquery/client.py", line 782, in _call_api
    return call()
  File "/home/airflow/.local/lib/python3.7/site-packages/google/api_core/retry.py", line 291, in retry_wrapped_func
    on_error=on_error,
  File "/home/airflow/.local/lib/python3.7/site-packages/google/api_core/retry.py", line 189, in retry_target
    return target()
  File "/home/airflow/.local/lib/python3.7/site-packages/google/cloud/_http.py", line 484, in api_request
    raise exceptions.from_http_response(response)
google.api_core.exceptions.BadRequest: 400 POST https://bigquery.googleapis.com/bigquery/v2/projects/wise-logic-354820/datasets/trips_data_all/tables?prettyPrint=false: Error while reading table: external_fhv_tripdata, error message: Input file is not in Parquet format. File: gs://dtc_data_lake_wise-logic-354820/fhv/_2019-12.parquet
[2022-08-05 17:11:40,537] {taskinstance.py:1277} INFO - Marking task as UP_FOR_RETRY. dag_id=move_gcs_trip_data_to_bq_workflow2, task_id=bigquery_external_table_task_fhv, execution_date=20220804T000000, start_date=20220805T171138, end_date=20220805T171140
[2022-08-05 17:11:40,654] {standard_task_runner.py:92} ERROR - Failed to execute job 104 for task bigquery_external_table_task_fhv
Traceback (most recent call last):
  File "/home/airflow/.local/lib/python3.7/site-packages/airflow/task/task_runner/standard_task_runner.py", line 85, in _start_by_fork
    args.func(args, dag=self.dag)
  File "/home/airflow/.local/lib/python3.7/site-packages/airflow/cli/cli_parser.py", line 48, in command
    return func(*args, **kwargs)
  File "/home/airflow/.local/lib/python3.7/site-packages/airflow/utils/cli.py", line 92, in wrapper
    return f(*args, **kwargs)
  File "/home/airflow/.local/lib/python3.7/site-packages/airflow/cli/commands/task_command.py", line 298, in task_run
    _run_task_by_selected_method(args, dag, ti)
  File "/home/airflow/.local/lib/python3.7/site-packages/airflow/cli/commands/task_command.py", line 107, in _run_task_by_selected_method
    _run_raw_task(args, ti)
  File "/home/airflow/.local/lib/python3.7/site-packages/airflow/cli/commands/task_command.py", line 184, in _run_raw_task
    error_file=args.error_file,
  File "/home/airflow/.local/lib/python3.7/site-packages/airflow/utils/session.py", line 70, in wrapper
    return func(*args, session=session, **kwargs)
  File "/home/airflow/.local/lib/python3.7/site-packages/airflow/models/taskinstance.py", line 1329, in _run_raw_task
    self._execute_task_with_callbacks(context)
  File "/home/airflow/.local/lib/python3.7/site-packages/airflow/models/taskinstance.py", line 1455, in _execute_task_with_callbacks
    result = self._execute_task(context, self.task)
  File "/home/airflow/.local/lib/python3.7/site-packages/airflow/models/taskinstance.py", line 1511, in _execute_task
    result = execute_callable(context=context)
  File "/home/airflow/.local/lib/python3.7/site-packages/airflow/providers/google/cloud/operators/bigquery.py", line 1196, in execute
    table_resource=self.table_resource,
  File "/home/airflow/.local/lib/python3.7/site-packages/airflow/providers/google/common/hooks/base_google.py", line 430, in inner_wrapper
    return func(self, *args, **kwargs)
  File "/home/airflow/.local/lib/python3.7/site-packages/airflow/providers/google/cloud/hooks/bigquery.py", line 408, in create_empty_table
    table=table, exists_ok=exists_ok, retry=retry
  File "/home/airflow/.local/lib/python3.7/site-packages/google/cloud/bigquery/client.py", line 755, in create_table
    timeout=timeout,
  File "/home/airflow/.local/lib/python3.7/site-packages/google/cloud/bigquery/client.py", line 782, in _call_api
    return call()
  File "/home/airflow/.local/lib/python3.7/site-packages/google/api_core/retry.py", line 291, in retry_wrapped_func
    on_error=on_error,
  File "/home/airflow/.local/lib/python3.7/site-packages/google/api_core/retry.py", line 189, in retry_target
    return target()
  File "/home/airflow/.local/lib/python3.7/site-packages/google/cloud/_http.py", line 484, in api_request
    raise exceptions.from_http_response(response)
google.api_core.exceptions.BadRequest: 400 POST https://bigquery.googleapis.com/bigquery/v2/projects/wise-logic-354820/datasets/trips_data_all/tables?prettyPrint=false: Error while reading table: external_fhv_tripdata, error message: Input file is not in Parquet format. File: gs://dtc_data_lake_wise-logic-354820/fhv/_2019-12.parquet
[2022-08-05 17:11:40,852] {local_task_job.py:154} INFO - Task exited with return code 1
[2022-08-05 17:11:41,044] {local_task_job.py:264} INFO - 0 downstream tasks scheduled from follow-on schedule check
