[2022-07-07 21:36:29,685] {taskinstance.py:1032} INFO - Dependencies all met for <TaskInstance: data_ingestion_gcs_full_yt.local_to_gcs_task manual__2022-07-07T20:45:21.502035+00:00 [queued]>
[2022-07-07 21:36:29,706] {taskinstance.py:1032} INFO - Dependencies all met for <TaskInstance: data_ingestion_gcs_full_yt.local_to_gcs_task manual__2022-07-07T20:45:21.502035+00:00 [queued]>
[2022-07-07 21:36:29,707] {taskinstance.py:1238} INFO - 
--------------------------------------------------------------------------------
[2022-07-07 21:36:29,709] {taskinstance.py:1239} INFO - Starting attempt 3 of 4
[2022-07-07 21:36:29,710] {taskinstance.py:1240} INFO - 
--------------------------------------------------------------------------------
[2022-07-07 21:36:29,732] {taskinstance.py:1259} INFO - Executing <Task(PythonOperator): local_to_gcs_task> on 2022-07-07 20:45:21.502035+00:00
[2022-07-07 21:36:29,746] {standard_task_runner.py:52} INFO - Started process 3254 to run task
[2022-07-07 21:36:29,751] {standard_task_runner.py:76} INFO - Running: ['***', 'tasks', 'run', 'data_ingestion_gcs_full_yt', 'local_to_gcs_task', 'manual__2022-07-07T20:45:21.502035+00:00', '--job-id', '126', '--raw', '--subdir', 'DAGS_FOLDER/data_ingestion_gcs_full_yt.py', '--cfg-path', '/tmp/tmpzzjv019k', '--error-file', '/tmp/tmp6wwt__0j']
[2022-07-07 21:36:29,760] {standard_task_runner.py:77} INFO - Job 126: Subtask local_to_gcs_task
[2022-07-07 21:36:29,856] {logging_mixin.py:109} INFO - Running <TaskInstance: data_ingestion_gcs_full_yt.local_to_gcs_task manual__2022-07-07T20:45:21.502035+00:00 [running]> on host 2b856f2081be
[2022-07-07 21:36:29,911] {taskinstance.py:1426} INFO - Exporting the following env vars:
AIRFLOW_CTX_DAG_OWNER=***
AIRFLOW_CTX_DAG_ID=data_ingestion_gcs_full_yt
AIRFLOW_CTX_TASK_ID=local_to_gcs_task
AIRFLOW_CTX_EXECUTION_DATE=2022-07-07T20:45:21.502035+00:00
AIRFLOW_CTX_DAG_RUN_ID=manual__2022-07-07T20:45:21.502035+00:00
[2022-07-07 21:36:29,935] {taskinstance.py:1700} ERROR - Task failed with exception
Traceback (most recent call last):
  File "/home/airflow/.local/lib/python3.6/site-packages/airflow/models/taskinstance.py", line 1329, in _run_raw_task
    self._execute_task_with_callbacks(context)
  File "/home/airflow/.local/lib/python3.6/site-packages/airflow/models/taskinstance.py", line 1455, in _execute_task_with_callbacks
    result = self._execute_task(context, self.task)
  File "/home/airflow/.local/lib/python3.6/site-packages/airflow/models/taskinstance.py", line 1511, in _execute_task
    result = execute_callable(context=context)
  File "/home/airflow/.local/lib/python3.6/site-packages/airflow/operators/python.py", line 174, in execute
    return_value = self.execute_callable()
  File "/home/airflow/.local/lib/python3.6/site-packages/airflow/operators/python.py", line 185, in execute_callable
    return self.python_callable(*self.op_args, **self.op_kwargs)
  File "/opt/airflow/dags/data_ingestion_gcs_full_yt.py", line 66, in upload_to_gcs
    blob.upload_from_filename(local_file)
  File "/home/airflow/.local/lib/python3.6/site-packages/google/cloud/storage/blob.py", line 2720, in upload_from_filename
    with open(filename, "rb") as file_obj:
FileNotFoundError: [Errno 2] No such file or directory: '/opt/airflow/output_42.parquet'
[2022-07-07 21:36:29,953] {taskinstance.py:1277} INFO - Marking task as UP_FOR_RETRY. dag_id=data_ingestion_gcs_full_yt, task_id=local_to_gcs_task, execution_date=20220707T204521, start_date=20220707T213629, end_date=20220707T213629
[2022-07-07 21:36:29,971] {standard_task_runner.py:92} ERROR - Failed to execute job 126 for task local_to_gcs_task
Traceback (most recent call last):
  File "/home/airflow/.local/lib/python3.6/site-packages/airflow/task/task_runner/standard_task_runner.py", line 85, in _start_by_fork
    args.func(args, dag=self.dag)
  File "/home/airflow/.local/lib/python3.6/site-packages/airflow/cli/cli_parser.py", line 48, in command
    return func(*args, **kwargs)
  File "/home/airflow/.local/lib/python3.6/site-packages/airflow/utils/cli.py", line 92, in wrapper
    return f(*args, **kwargs)
  File "/home/airflow/.local/lib/python3.6/site-packages/airflow/cli/commands/task_command.py", line 298, in task_run
    _run_task_by_selected_method(args, dag, ti)
  File "/home/airflow/.local/lib/python3.6/site-packages/airflow/cli/commands/task_command.py", line 107, in _run_task_by_selected_method
    _run_raw_task(args, ti)
  File "/home/airflow/.local/lib/python3.6/site-packages/airflow/cli/commands/task_command.py", line 184, in _run_raw_task
    error_file=args.error_file,
  File "/home/airflow/.local/lib/python3.6/site-packages/airflow/utils/session.py", line 70, in wrapper
    return func(*args, session=session, **kwargs)
  File "/home/airflow/.local/lib/python3.6/site-packages/airflow/models/taskinstance.py", line 1329, in _run_raw_task
    self._execute_task_with_callbacks(context)
  File "/home/airflow/.local/lib/python3.6/site-packages/airflow/models/taskinstance.py", line 1455, in _execute_task_with_callbacks
    result = self._execute_task(context, self.task)
  File "/home/airflow/.local/lib/python3.6/site-packages/airflow/models/taskinstance.py", line 1511, in _execute_task
    result = execute_callable(context=context)
  File "/home/airflow/.local/lib/python3.6/site-packages/airflow/operators/python.py", line 174, in execute
    return_value = self.execute_callable()
  File "/home/airflow/.local/lib/python3.6/site-packages/airflow/operators/python.py", line 185, in execute_callable
    return self.python_callable(*self.op_args, **self.op_kwargs)
  File "/opt/airflow/dags/data_ingestion_gcs_full_yt.py", line 66, in upload_to_gcs
    blob.upload_from_filename(local_file)
  File "/home/airflow/.local/lib/python3.6/site-packages/google/cloud/storage/blob.py", line 2720, in upload_from_filename
    with open(filename, "rb") as file_obj:
FileNotFoundError: [Errno 2] No such file or directory: '/opt/airflow/output_42.parquet'
[2022-07-07 21:36:30,021] {local_task_job.py:154} INFO - Task exited with return code 1
[2022-07-07 21:36:30,063] {local_task_job.py:264} INFO - 0 downstream tasks scheduled from follow-on schedule check
