[2022-07-05 15:28:26,658] {taskinstance.py:1032} INFO - Dependencies all met for <TaskInstance: LocalIngestionDag.wget manual__2022-07-05T15:28:25.033643+00:00 [queued]>
[2022-07-05 15:28:26,708] {taskinstance.py:1032} INFO - Dependencies all met for <TaskInstance: LocalIngestionDag.wget manual__2022-07-05T15:28:25.033643+00:00 [queued]>
[2022-07-05 15:28:26,710] {taskinstance.py:1238} INFO - 
--------------------------------------------------------------------------------
[2022-07-05 15:28:26,711] {taskinstance.py:1239} INFO - Starting attempt 1 of 1
[2022-07-05 15:28:26,712] {taskinstance.py:1240} INFO - 
--------------------------------------------------------------------------------
[2022-07-05 15:28:26,737] {taskinstance.py:1259} INFO - Executing <Task(BashOperator): wget> on 2022-07-05 15:28:25.033643+00:00
[2022-07-05 15:28:26,762] {standard_task_runner.py:76} INFO - Running: ['***', 'tasks', 'run', 'LocalIngestionDag', 'wget', 'manual__2022-07-05T15:28:25.033643+00:00', '--job-id', '45', '--raw', '--subdir', 'DAGS_FOLDER/data_ingestion_local.py', '--cfg-path', '/tmp/tmpy1kejo68', '--error-file', '/tmp/tmph0s3o0_e']
[2022-07-05 15:28:26,755] {standard_task_runner.py:52} INFO - Started process 243 to run task
[2022-07-05 15:28:26,765] {standard_task_runner.py:77} INFO - Job 45: Subtask wget
[2022-07-05 15:28:26,874] {logging_mixin.py:109} INFO - Running <TaskInstance: LocalIngestionDag.wget manual__2022-07-05T15:28:25.033643+00:00 [running]> on host 730d3c67d882
[2022-07-05 15:28:27,006] {taskinstance.py:1426} INFO - Exporting the following env vars:
AIRFLOW_CTX_DAG_OWNER=***
AIRFLOW_CTX_DAG_ID=LocalIngestionDag
AIRFLOW_CTX_TASK_ID=wget
AIRFLOW_CTX_EXECUTION_DATE=2022-07-05T15:28:25.033643+00:00
AIRFLOW_CTX_DAG_RUN_ID=manual__2022-07-05T15:28:25.033643+00:00
[2022-07-05 15:28:27,011] {subprocess.py:62} INFO - Tmp dir root location: 
 /tmp
[2022-07-05 15:28:27,016] {subprocess.py:74} INFO - Running command: ['bash', '-c', 'ech "hello world"']
[2022-07-05 15:28:27,064] {subprocess.py:85} INFO - Output:
[2022-07-05 15:28:27,074] {subprocess.py:89} INFO - bash: ech: command not found
[2022-07-05 15:28:27,077] {subprocess.py:93} INFO - Command exited with return code 127
[2022-07-05 15:28:27,134] {taskinstance.py:1700} ERROR - Task failed with exception
Traceback (most recent call last):
  File "/home/airflow/.local/lib/python3.6/site-packages/airflow/models/taskinstance.py", line 1329, in _run_raw_task
    self._execute_task_with_callbacks(context)
  File "/home/airflow/.local/lib/python3.6/site-packages/airflow/models/taskinstance.py", line 1455, in _execute_task_with_callbacks
    result = self._execute_task(context, self.task)
  File "/home/airflow/.local/lib/python3.6/site-packages/airflow/models/taskinstance.py", line 1511, in _execute_task
    result = execute_callable(context=context)
  File "/home/airflow/.local/lib/python3.6/site-packages/airflow/operators/bash.py", line 188, in execute
    f'Bash command failed. The command returned a non-zero exit code {result.exit_code}.'
airflow.exceptions.AirflowException: Bash command failed. The command returned a non-zero exit code 127.
[2022-07-05 15:28:27,151] {taskinstance.py:1277} INFO - Marking task as FAILED. dag_id=LocalIngestionDag, task_id=wget, execution_date=20220705T152825, start_date=20220705T152826, end_date=20220705T152827
[2022-07-05 15:28:27,185] {standard_task_runner.py:92} ERROR - Failed to execute job 45 for task wget
Traceback (most recent call last):
  File "/home/airflow/.local/lib/python3.6/site-packages/airflow/task/task_runner/standard_task_runner.py", line 85, in _start_by_fork
    args.func(args, dag=self.dag)
  File "/home/airflow/.local/lib/python3.6/site-packages/airflow/cli/cli_parser.py", line 48, in command
    return func(*args, **kwargs)
  File "/home/airflow/.local/lib/python3.6/site-packages/airflow/utils/cli.py", line 92, in wrapper
    return f(*args, **kwargs)
  File "/home/airflow/.local/lib/python3.6/site-packages/airflow/cli/commands/task_command.py", line 298, in task_run
    _run_task_by_selected_method(args, dag, ti)
  File "/home/airflow/.local/lib/python3.6/site-packages/airflow/cli/commands/task_command.py", line 107, in _run_task_by_selected_method
    _run_raw_task(args, ti)
  File "/home/airflow/.local/lib/python3.6/site-packages/airflow/cli/commands/task_command.py", line 184, in _run_raw_task
    error_file=args.error_file,
  File "/home/airflow/.local/lib/python3.6/site-packages/airflow/utils/session.py", line 70, in wrapper
    return func(*args, session=session, **kwargs)
  File "/home/airflow/.local/lib/python3.6/site-packages/airflow/models/taskinstance.py", line 1329, in _run_raw_task
    self._execute_task_with_callbacks(context)
  File "/home/airflow/.local/lib/python3.6/site-packages/airflow/models/taskinstance.py", line 1455, in _execute_task_with_callbacks
    result = self._execute_task(context, self.task)
  File "/home/airflow/.local/lib/python3.6/site-packages/airflow/models/taskinstance.py", line 1511, in _execute_task
    result = execute_callable(context=context)
  File "/home/airflow/.local/lib/python3.6/site-packages/airflow/operators/bash.py", line 188, in execute
    f'Bash command failed. The command returned a non-zero exit code {result.exit_code}.'
airflow.exceptions.AirflowException: Bash command failed. The command returned a non-zero exit code 127.
[2022-07-05 15:28:27,248] {local_task_job.py:154} INFO - Task exited with return code 1
[2022-07-05 15:28:27,479] {local_task_job.py:264} INFO - 0 downstream tasks scheduled from follow-on schedule check
