[2022-07-07 20:38:22,233] {taskinstance.py:1032} INFO - Dependencies all met for <TaskInstance: data_ingestion_gcs_full_yt.download_dataset_task scheduled__2022-06-02T06:00:00+00:00 [queued]>
[2022-07-07 20:38:22,250] {taskinstance.py:1032} INFO - Dependencies all met for <TaskInstance: data_ingestion_gcs_full_yt.download_dataset_task scheduled__2022-06-02T06:00:00+00:00 [queued]>
[2022-07-07 20:38:22,251] {taskinstance.py:1238} INFO - 
--------------------------------------------------------------------------------
[2022-07-07 20:38:22,252] {taskinstance.py:1239} INFO - Starting attempt 1 of 2
[2022-07-07 20:38:22,253] {taskinstance.py:1240} INFO - 
--------------------------------------------------------------------------------
[2022-07-07 20:38:22,266] {taskinstance.py:1259} INFO - Executing <Task(BashOperator): download_dataset_task> on 2022-06-02 06:00:00+00:00
[2022-07-07 20:38:22,272] {standard_task_runner.py:52} INFO - Started process 462 to run task
[2022-07-07 20:38:22,279] {standard_task_runner.py:76} INFO - Running: ['***', 'tasks', 'run', 'data_ingestion_gcs_full_yt', 'download_dataset_task', 'scheduled__2022-06-02T06:00:00+00:00', '--job-id', '93', '--raw', '--subdir', 'DAGS_FOLDER/data_ingestion_gcs_full_yt.py', '--cfg-path', '/tmp/tmpo09n2a_7', '--error-file', '/tmp/tmpzrld2pi5']
[2022-07-07 20:38:22,283] {standard_task_runner.py:77} INFO - Job 93: Subtask download_dataset_task
[2022-07-07 20:38:22,353] {logging_mixin.py:109} INFO - Running <TaskInstance: data_ingestion_gcs_full_yt.download_dataset_task scheduled__2022-06-02T06:00:00+00:00 [running]> on host 2b856f2081be
[2022-07-07 20:38:22,422] {warnings.py:99} WARNING - /home/***/.local/lib/python3.6/site-packages/***/utils/context.py:152: AirflowContextDeprecationWarning: Accessing 'execution_date' from the template is deprecated and will be removed in a future version. Please use 'data_interval_start' or 'logical_date' instead.
  warnings.warn(_create_deprecation_warning(key, self._deprecation_replacements[key]))

[2022-07-07 20:38:22,454] {taskinstance.py:1426} INFO - Exporting the following env vars:
AIRFLOW_CTX_DAG_OWNER=***
AIRFLOW_CTX_DAG_ID=data_ingestion_gcs_full_yt
AIRFLOW_CTX_TASK_ID=download_dataset_task
AIRFLOW_CTX_EXECUTION_DATE=2022-06-02T06:00:00+00:00
AIRFLOW_CTX_DAG_RUN_ID=scheduled__2022-06-02T06:00:00+00:00
[2022-07-07 20:38:22,456] {subprocess.py:62} INFO - Tmp dir root location: 
 /tmp
[2022-07-07 20:38:22,458] {subprocess.py:74} INFO - Running command: ['bash', '-c', 'curl -sSL https://d37ci6vzurychx.cloudfront.net/trip-data/yellow_tripdata_2022-06.csv > /opt/***//opt/***/output_2022-06.csv']
[2022-07-07 20:38:22,475] {subprocess.py:85} INFO - Output:
[2022-07-07 20:38:22,479] {subprocess.py:89} INFO - bash: /opt/***//opt/***/output_2022-06.csv: No such file or directory
[2022-07-07 20:38:22,480] {subprocess.py:93} INFO - Command exited with return code 1
[2022-07-07 20:38:22,498] {taskinstance.py:1700} ERROR - Task failed with exception
Traceback (most recent call last):
  File "/home/airflow/.local/lib/python3.6/site-packages/airflow/models/taskinstance.py", line 1329, in _run_raw_task
    self._execute_task_with_callbacks(context)
  File "/home/airflow/.local/lib/python3.6/site-packages/airflow/models/taskinstance.py", line 1455, in _execute_task_with_callbacks
    result = self._execute_task(context, self.task)
  File "/home/airflow/.local/lib/python3.6/site-packages/airflow/models/taskinstance.py", line 1511, in _execute_task
    result = execute_callable(context=context)
  File "/home/airflow/.local/lib/python3.6/site-packages/airflow/operators/bash.py", line 188, in execute
    f'Bash command failed. The command returned a non-zero exit code {result.exit_code}.'
airflow.exceptions.AirflowException: Bash command failed. The command returned a non-zero exit code 1.
[2022-07-07 20:38:22,507] {taskinstance.py:1277} INFO - Marking task as UP_FOR_RETRY. dag_id=data_ingestion_gcs_full_yt, task_id=download_dataset_task, execution_date=20220602T060000, start_date=20220707T203822, end_date=20220707T203822
[2022-07-07 20:38:22,524] {standard_task_runner.py:92} ERROR - Failed to execute job 93 for task download_dataset_task
Traceback (most recent call last):
  File "/home/airflow/.local/lib/python3.6/site-packages/airflow/task/task_runner/standard_task_runner.py", line 85, in _start_by_fork
    args.func(args, dag=self.dag)
  File "/home/airflow/.local/lib/python3.6/site-packages/airflow/cli/cli_parser.py", line 48, in command
    return func(*args, **kwargs)
  File "/home/airflow/.local/lib/python3.6/site-packages/airflow/utils/cli.py", line 92, in wrapper
    return f(*args, **kwargs)
  File "/home/airflow/.local/lib/python3.6/site-packages/airflow/cli/commands/task_command.py", line 298, in task_run
    _run_task_by_selected_method(args, dag, ti)
  File "/home/airflow/.local/lib/python3.6/site-packages/airflow/cli/commands/task_command.py", line 107, in _run_task_by_selected_method
    _run_raw_task(args, ti)
  File "/home/airflow/.local/lib/python3.6/site-packages/airflow/cli/commands/task_command.py", line 184, in _run_raw_task
    error_file=args.error_file,
  File "/home/airflow/.local/lib/python3.6/site-packages/airflow/utils/session.py", line 70, in wrapper
    return func(*args, session=session, **kwargs)
  File "/home/airflow/.local/lib/python3.6/site-packages/airflow/models/taskinstance.py", line 1329, in _run_raw_task
    self._execute_task_with_callbacks(context)
  File "/home/airflow/.local/lib/python3.6/site-packages/airflow/models/taskinstance.py", line 1455, in _execute_task_with_callbacks
    result = self._execute_task(context, self.task)
  File "/home/airflow/.local/lib/python3.6/site-packages/airflow/models/taskinstance.py", line 1511, in _execute_task
    result = execute_callable(context=context)
  File "/home/airflow/.local/lib/python3.6/site-packages/airflow/operators/bash.py", line 188, in execute
    f'Bash command failed. The command returned a non-zero exit code {result.exit_code}.'
airflow.exceptions.AirflowException: Bash command failed. The command returned a non-zero exit code 1.
[2022-07-07 20:38:22,580] {local_task_job.py:154} INFO - Task exited with return code 1
[2022-07-07 20:38:22,626] {local_task_job.py:264} INFO - 0 downstream tasks scheduled from follow-on schedule check
