[2022-07-07 21:14:37,497] {taskinstance.py:1032} INFO - Dependencies all met for <TaskInstance: data_ingestion_gcs_full_yt.download_dataset_task scheduled__2022-06-02T06:00:00+00:00 [queued]>
[2022-07-07 21:14:37,512] {taskinstance.py:1032} INFO - Dependencies all met for <TaskInstance: data_ingestion_gcs_full_yt.download_dataset_task scheduled__2022-06-02T06:00:00+00:00 [queued]>
[2022-07-07 21:14:37,514] {taskinstance.py:1238} INFO - 
--------------------------------------------------------------------------------
[2022-07-07 21:14:37,515] {taskinstance.py:1239} INFO - Starting attempt 4 of 5
[2022-07-07 21:14:37,516] {taskinstance.py:1240} INFO - 
--------------------------------------------------------------------------------
[2022-07-07 21:14:37,534] {taskinstance.py:1259} INFO - Executing <Task(BashOperator): download_dataset_task> on 2022-06-02 06:00:00+00:00
[2022-07-07 21:14:37,549] {standard_task_runner.py:76} INFO - Running: ['***', 'tasks', 'run', 'data_ingestion_gcs_full_yt', 'download_dataset_task', 'scheduled__2022-06-02T06:00:00+00:00', '--job-id', '105', '--raw', '--subdir', 'DAGS_FOLDER/data_ingestion_gcs_full_yt.py', '--cfg-path', '/tmp/tmpyt4xty6k', '--error-file', '/tmp/tmp2njff4le']
[2022-07-07 21:14:37,543] {standard_task_runner.py:52} INFO - Started process 2183 to run task
[2022-07-07 21:14:37,555] {standard_task_runner.py:77} INFO - Job 105: Subtask download_dataset_task
[2022-07-07 21:14:37,634] {logging_mixin.py:109} INFO - Running <TaskInstance: data_ingestion_gcs_full_yt.download_dataset_task scheduled__2022-06-02T06:00:00+00:00 [running]> on host 2b856f2081be
[2022-07-07 21:14:37,718] {taskinstance.py:1426} INFO - Exporting the following env vars:
AIRFLOW_CTX_DAG_OWNER=***
AIRFLOW_CTX_DAG_ID=data_ingestion_gcs_full_yt
AIRFLOW_CTX_TASK_ID=download_dataset_task
AIRFLOW_CTX_EXECUTION_DATE=2022-06-02T06:00:00+00:00
AIRFLOW_CTX_DAG_RUN_ID=scheduled__2022-06-02T06:00:00+00:00
[2022-07-07 21:14:37,722] {subprocess.py:62} INFO - Tmp dir root location: 
 /tmp
[2022-07-07 21:14:37,724] {subprocess.py:74} INFO - Running command: ['bash', '-c', 'curl -sSL https://d37ci6vzurychx.cloudfront.net/trip-data/yellow_tripdata_2019-07-01.parquet > /opt/***//opt/***/output_2019-07-01.parquet']
[2022-07-07 21:14:37,739] {subprocess.py:85} INFO - Output:
[2022-07-07 21:14:37,744] {subprocess.py:89} INFO - bash: /opt/***//opt/***/output_2019-07-01.parquet: No such file or directory
[2022-07-07 21:14:37,745] {subprocess.py:93} INFO - Command exited with return code 1
[2022-07-07 21:14:37,768] {taskinstance.py:1700} ERROR - Task failed with exception
Traceback (most recent call last):
  File "/home/airflow/.local/lib/python3.6/site-packages/airflow/models/taskinstance.py", line 1329, in _run_raw_task
    self._execute_task_with_callbacks(context)
  File "/home/airflow/.local/lib/python3.6/site-packages/airflow/models/taskinstance.py", line 1455, in _execute_task_with_callbacks
    result = self._execute_task(context, self.task)
  File "/home/airflow/.local/lib/python3.6/site-packages/airflow/models/taskinstance.py", line 1511, in _execute_task
    result = execute_callable(context=context)
  File "/home/airflow/.local/lib/python3.6/site-packages/airflow/operators/bash.py", line 188, in execute
    f'Bash command failed. The command returned a non-zero exit code {result.exit_code}.'
airflow.exceptions.AirflowException: Bash command failed. The command returned a non-zero exit code 1.
[2022-07-07 21:14:37,781] {taskinstance.py:1277} INFO - Marking task as UP_FOR_RETRY. dag_id=data_ingestion_gcs_full_yt, task_id=download_dataset_task, execution_date=20220602T060000, start_date=20220707T211437, end_date=20220707T211437
[2022-07-07 21:14:37,803] {standard_task_runner.py:92} ERROR - Failed to execute job 105 for task download_dataset_task
Traceback (most recent call last):
  File "/home/airflow/.local/lib/python3.6/site-packages/airflow/task/task_runner/standard_task_runner.py", line 85, in _start_by_fork
    args.func(args, dag=self.dag)
  File "/home/airflow/.local/lib/python3.6/site-packages/airflow/cli/cli_parser.py", line 48, in command
    return func(*args, **kwargs)
  File "/home/airflow/.local/lib/python3.6/site-packages/airflow/utils/cli.py", line 92, in wrapper
    return f(*args, **kwargs)
  File "/home/airflow/.local/lib/python3.6/site-packages/airflow/cli/commands/task_command.py", line 298, in task_run
    _run_task_by_selected_method(args, dag, ti)
  File "/home/airflow/.local/lib/python3.6/site-packages/airflow/cli/commands/task_command.py", line 107, in _run_task_by_selected_method
    _run_raw_task(args, ti)
  File "/home/airflow/.local/lib/python3.6/site-packages/airflow/cli/commands/task_command.py", line 184, in _run_raw_task
    error_file=args.error_file,
  File "/home/airflow/.local/lib/python3.6/site-packages/airflow/utils/session.py", line 70, in wrapper
    return func(*args, session=session, **kwargs)
  File "/home/airflow/.local/lib/python3.6/site-packages/airflow/models/taskinstance.py", line 1329, in _run_raw_task
    self._execute_task_with_callbacks(context)
  File "/home/airflow/.local/lib/python3.6/site-packages/airflow/models/taskinstance.py", line 1455, in _execute_task_with_callbacks
    result = self._execute_task(context, self.task)
  File "/home/airflow/.local/lib/python3.6/site-packages/airflow/models/taskinstance.py", line 1511, in _execute_task
    result = execute_callable(context=context)
  File "/home/airflow/.local/lib/python3.6/site-packages/airflow/operators/bash.py", line 188, in execute
    f'Bash command failed. The command returned a non-zero exit code {result.exit_code}.'
airflow.exceptions.AirflowException: Bash command failed. The command returned a non-zero exit code 1.
[2022-07-07 21:14:37,853] {local_task_job.py:154} INFO - Task exited with return code 1
[2022-07-07 21:14:37,910] {local_task_job.py:264} INFO - 0 downstream tasks scheduled from follow-on schedule check
