[2022-07-07 21:17:28,832] {taskinstance.py:1032} INFO - Dependencies all met for <TaskInstance: data_ingestion_gcs_full_yt.download_dataset_task scheduled__2022-06-02T06:00:00+00:00 [queued]>
[2022-07-07 21:17:28,920] {taskinstance.py:1032} INFO - Dependencies all met for <TaskInstance: data_ingestion_gcs_full_yt.download_dataset_task scheduled__2022-06-02T06:00:00+00:00 [queued]>
[2022-07-07 21:17:28,922] {taskinstance.py:1238} INFO - 
--------------------------------------------------------------------------------
[2022-07-07 21:17:28,926] {taskinstance.py:1239} INFO - Starting attempt 5 of 6
[2022-07-07 21:17:28,927] {taskinstance.py:1240} INFO - 
--------------------------------------------------------------------------------
[2022-07-07 21:17:29,012] {taskinstance.py:1259} INFO - Executing <Task(BashOperator): download_dataset_task> on 2022-06-02 06:00:00+00:00
[2022-07-07 21:17:29,039] {standard_task_runner.py:52} INFO - Started process 2306 to run task
[2022-07-07 21:17:29,055] {standard_task_runner.py:76} INFO - Running: ['***', 'tasks', 'run', 'data_ingestion_gcs_full_yt', 'download_dataset_task', 'scheduled__2022-06-02T06:00:00+00:00', '--job-id', '106', '--raw', '--subdir', 'DAGS_FOLDER/data_ingestion_gcs_full_yt.py', '--cfg-path', '/tmp/tmpfd4c3eu_', '--error-file', '/tmp/tmpymvvcw0_']
[2022-07-07 21:17:29,094] {standard_task_runner.py:77} INFO - Job 106: Subtask download_dataset_task
[2022-07-07 21:17:29,286] {logging_mixin.py:109} INFO - Running <TaskInstance: data_ingestion_gcs_full_yt.download_dataset_task scheduled__2022-06-02T06:00:00+00:00 [running]> on host 2b856f2081be
[2022-07-07 21:17:29,404] {taskinstance.py:1426} INFO - Exporting the following env vars:
AIRFLOW_CTX_DAG_OWNER=***
AIRFLOW_CTX_DAG_ID=data_ingestion_gcs_full_yt
AIRFLOW_CTX_TASK_ID=download_dataset_task
AIRFLOW_CTX_EXECUTION_DATE=2022-06-02T06:00:00+00:00
AIRFLOW_CTX_DAG_RUN_ID=scheduled__2022-06-02T06:00:00+00:00
[2022-07-07 21:17:29,417] {subprocess.py:62} INFO - Tmp dir root location: 
 /tmp
[2022-07-07 21:17:29,420] {subprocess.py:74} INFO - Running command: ['bash', '-c', 'curl -sSL https://d37ci6vzurychx.cloudfront.net/trip-data/yellow_tripdata_2019-01-01.parquet > /opt/***//opt/***output_2019-01-01.parquet']
[2022-07-07 21:17:29,437] {subprocess.py:85} INFO - Output:
[2022-07-07 21:17:29,442] {subprocess.py:89} INFO - bash: /opt/***//opt/***output_2019-01-01.parquet: No such file or directory
[2022-07-07 21:17:29,445] {subprocess.py:93} INFO - Command exited with return code 1
[2022-07-07 21:17:29,482] {taskinstance.py:1700} ERROR - Task failed with exception
Traceback (most recent call last):
  File "/home/airflow/.local/lib/python3.6/site-packages/airflow/models/taskinstance.py", line 1329, in _run_raw_task
    self._execute_task_with_callbacks(context)
  File "/home/airflow/.local/lib/python3.6/site-packages/airflow/models/taskinstance.py", line 1455, in _execute_task_with_callbacks
    result = self._execute_task(context, self.task)
  File "/home/airflow/.local/lib/python3.6/site-packages/airflow/models/taskinstance.py", line 1511, in _execute_task
    result = execute_callable(context=context)
  File "/home/airflow/.local/lib/python3.6/site-packages/airflow/operators/bash.py", line 188, in execute
    f'Bash command failed. The command returned a non-zero exit code {result.exit_code}.'
airflow.exceptions.AirflowException: Bash command failed. The command returned a non-zero exit code 1.
[2022-07-07 21:17:29,499] {taskinstance.py:1277} INFO - Marking task as UP_FOR_RETRY. dag_id=data_ingestion_gcs_full_yt, task_id=download_dataset_task, execution_date=20220602T060000, start_date=20220707T211728, end_date=20220707T211729
[2022-07-07 21:17:29,534] {standard_task_runner.py:92} ERROR - Failed to execute job 106 for task download_dataset_task
Traceback (most recent call last):
  File "/home/airflow/.local/lib/python3.6/site-packages/airflow/task/task_runner/standard_task_runner.py", line 85, in _start_by_fork
    args.func(args, dag=self.dag)
  File "/home/airflow/.local/lib/python3.6/site-packages/airflow/cli/cli_parser.py", line 48, in command
    return func(*args, **kwargs)
  File "/home/airflow/.local/lib/python3.6/site-packages/airflow/utils/cli.py", line 92, in wrapper
    return f(*args, **kwargs)
  File "/home/airflow/.local/lib/python3.6/site-packages/airflow/cli/commands/task_command.py", line 298, in task_run
    _run_task_by_selected_method(args, dag, ti)
  File "/home/airflow/.local/lib/python3.6/site-packages/airflow/cli/commands/task_command.py", line 107, in _run_task_by_selected_method
    _run_raw_task(args, ti)
  File "/home/airflow/.local/lib/python3.6/site-packages/airflow/cli/commands/task_command.py", line 184, in _run_raw_task
    error_file=args.error_file,
  File "/home/airflow/.local/lib/python3.6/site-packages/airflow/utils/session.py", line 70, in wrapper
    return func(*args, session=session, **kwargs)
  File "/home/airflow/.local/lib/python3.6/site-packages/airflow/models/taskinstance.py", line 1329, in _run_raw_task
    self._execute_task_with_callbacks(context)
  File "/home/airflow/.local/lib/python3.6/site-packages/airflow/models/taskinstance.py", line 1455, in _execute_task_with_callbacks
    result = self._execute_task(context, self.task)
  File "/home/airflow/.local/lib/python3.6/site-packages/airflow/models/taskinstance.py", line 1511, in _execute_task
    result = execute_callable(context=context)
  File "/home/airflow/.local/lib/python3.6/site-packages/airflow/operators/bash.py", line 188, in execute
    f'Bash command failed. The command returned a non-zero exit code {result.exit_code}.'
airflow.exceptions.AirflowException: Bash command failed. The command returned a non-zero exit code 1.
[2022-07-07 21:17:29,594] {local_task_job.py:154} INFO - Task exited with return code 1
[2022-07-07 21:17:29,695] {local_task_job.py:264} INFO - 0 downstream tasks scheduled from follow-on schedule check
